2018-09-28 10:19:00,385 ERROR: Exception on /unfollow/david [GET] [in c:\users\cleo\documents\github\flaskblog\venv\lib\site-packages\flask\app.py:1761]
Traceback (most recent call last):
  File "c:\users\cleo\documents\github\flaskblog\venv\lib\site-packages\flask\app.py", line 2292, in wsgi_app
    response = self.full_dispatch_request()
  File "c:\users\cleo\documents\github\flaskblog\venv\lib\site-packages\flask\app.py", line 1815, in full_dispatch_request
    rv = self.handle_user_exception(e)
  File "c:\users\cleo\documents\github\flaskblog\venv\lib\site-packages\flask\app.py", line 1718, in handle_user_exception
    reraise(exc_type, exc_value, tb)
  File "c:\users\cleo\documents\github\flaskblog\venv\lib\site-packages\flask\_compat.py", line 35, in reraise
    raise value
  File "c:\users\cleo\documents\github\flaskblog\venv\lib\site-packages\flask\app.py", line 1813, in full_dispatch_request
    rv = self.dispatch_request()
  File "c:\users\cleo\documents\github\flaskblog\venv\lib\site-packages\flask\app.py", line 1799, in dispatch_request
    return self.view_functions[rule.endpoint](**req.view_args)
  File "c:\users\cleo\documents\github\flaskblog\venv\lib\site-packages\flask_login\utils.py", line 261, in decorated_view
    return func(*args, **kwargs)
  File "C:\Users\Cleo\Documents\GitHub\FlaskBlog\app\routes.py", line 133, in unfollow
    return redirect(url_for('user'), username=username)
  File "c:\users\cleo\documents\github\flaskblog\venv\lib\site-packages\flask\helpers.py", line 356, in url_for
    return appctx.app.handle_url_build_error(error, endpoint, values)
  File "c:\users\cleo\documents\github\flaskblog\venv\lib\site-packages\flask\app.py", line 2061, in handle_url_build_error
    reraise(exc_type, exc_value, tb)
  File "c:\users\cleo\documents\github\flaskblog\venv\lib\site-packages\flask\_compat.py", line 35, in reraise
    raise value
  File "c:\users\cleo\documents\github\flaskblog\venv\lib\site-packages\flask\helpers.py", line 345, in url_for
    force_external=external)
  File "c:\users\cleo\documents\github\flaskblog\venv\lib\site-packages\werkzeug\routing.py", line 1776, in build
    raise BuildError(endpoint, values, method, self)
werkzeug.routing.BuildError: Could not build url for endpoint 'user'. Did you forget to specify values ['username']?
2018-09-28 10:21:35,661 INFO: Flaskblog startup [in C:\Users\Cleo\Documents\GitHub\FlaskBlog\app\__init__.py:49]
2018-09-28 11:00:17,889 INFO: Flaskblog startup [in C:\Users\Cleo\Documents\GitHub\FlaskBlog\app\__init__.py:49]
2018-09-28 11:00:25,902 ERROR: Exception on /index [GET] [in c:\users\cleo\documents\github\flaskblog\venv\lib\site-packages\flask\app.py:1761]
Traceback (most recent call last):
  File "c:\users\cleo\documents\github\flaskblog\venv\lib\site-packages\flask\app.py", line 2292, in wsgi_app
    response = self.full_dispatch_request()
  File "c:\users\cleo\documents\github\flaskblog\venv\lib\site-packages\flask\app.py", line 1815, in full_dispatch_request
    rv = self.handle_user_exception(e)
  File "c:\users\cleo\documents\github\flaskblog\venv\lib\site-packages\flask\app.py", line 1718, in handle_user_exception
    reraise(exc_type, exc_value, tb)
  File "c:\users\cleo\documents\github\flaskblog\venv\lib\site-packages\flask\_compat.py", line 35, in reraise
    raise value
  File "c:\users\cleo\documents\github\flaskblog\venv\lib\site-packages\flask\app.py", line 1813, in full_dispatch_request
    rv = self.dispatch_request()
  File "c:\users\cleo\documents\github\flaskblog\venv\lib\site-packages\flask\app.py", line 1799, in dispatch_request
    return self.view_functions[rule.endpoint](**req.view_args)
  File "c:\users\cleo\documents\github\flaskblog\venv\lib\site-packages\flask_login\utils.py", line 261, in decorated_view
    return func(*args, **kwargs)
  File "C:\Users\Cleo\Documents\GitHub\FlaskBlog\app\routes.py", line 22, in index
    posts = current_user.followed_post().all()
  File "c:\users\cleo\documents\github\flaskblog\venv\lib\site-packages\werkzeug\local.py", line 347, in __getattr__
    return getattr(self._get_current_object(), name)
AttributeError: 'User' object has no attribute 'followed_post'
2018-09-28 11:01:07,513 INFO: Flaskblog startup [in C:\Users\Cleo\Documents\GitHub\FlaskBlog\app\__init__.py:49]
2018-09-28 11:01:12,161 ERROR: Exception on /index [GET] [in c:\users\cleo\documents\github\flaskblog\venv\lib\site-packages\flask\app.py:1761]
Traceback (most recent call last):
  File "c:\users\cleo\documents\github\flaskblog\venv\lib\site-packages\flask\app.py", line 2292, in wsgi_app
    response = self.full_dispatch_request()
  File "c:\users\cleo\documents\github\flaskblog\venv\lib\site-packages\flask\app.py", line 1815, in full_dispatch_request
    rv = self.handle_user_exception(e)
  File "c:\users\cleo\documents\github\flaskblog\venv\lib\site-packages\flask\app.py", line 1718, in handle_user_exception
    reraise(exc_type, exc_value, tb)
  File "c:\users\cleo\documents\github\flaskblog\venv\lib\site-packages\flask\_compat.py", line 35, in reraise
    raise value
  File "c:\users\cleo\documents\github\flaskblog\venv\lib\site-packages\flask\app.py", line 1813, in full_dispatch_request
    rv = self.dispatch_request()
  File "c:\users\cleo\documents\github\flaskblog\venv\lib\site-packages\flask\app.py", line 1799, in dispatch_request
    return self.view_functions[rule.endpoint](**req.view_args)
  File "c:\users\cleo\documents\github\flaskblog\venv\lib\site-packages\flask_login\utils.py", line 261, in decorated_view
    return func(*args, **kwargs)
  File "C:\Users\Cleo\Documents\GitHub\FlaskBlog\app\routes.py", line 24, in index
    posts=posts)
  File "c:\users\cleo\documents\github\flaskblog\venv\lib\site-packages\flask\templating.py", line 135, in render_template
    context, ctx.app)
  File "c:\users\cleo\documents\github\flaskblog\venv\lib\site-packages\flask\templating.py", line 117, in _render
    rv = template.render(context)
  File "c:\users\cleo\documents\github\flaskblog\venv\lib\site-packages\jinja2\asyncsupport.py", line 76, in render
    return original_render(self, *args, **kwargs)
  File "c:\users\cleo\documents\github\flaskblog\venv\lib\site-packages\jinja2\environment.py", line 1008, in render
    return self.environment.handle_exception(exc_info, True)
  File "c:\users\cleo\documents\github\flaskblog\venv\lib\site-packages\jinja2\environment.py", line 780, in handle_exception
    reraise(exc_type, exc_value, tb)
  File "c:\users\cleo\documents\github\flaskblog\venv\lib\site-packages\jinja2\_compat.py", line 37, in reraise
    raise value.with_traceback(tb)
  File "C:\Users\Cleo\Documents\GitHub\FlaskBlog\app\templates\index.html", line 1, in top-level template code
    {% extends "base.html" %}
  File "C:\Users\Cleo\Documents\GitHub\FlaskBlog\app\templates\base.html", line 30, in top-level template code
    {% block content %}
  File "C:\Users\Cleo\Documents\GitHub\FlaskBlog\app\templates\index.html", line 6, in block "content"
    {{ form.hidden_tag() }}
  File "c:\users\cleo\documents\github\flaskblog\venv\lib\site-packages\jinja2\environment.py", line 430, in getattr
    return getattr(obj, attribute)
jinja2.exceptions.UndefinedError: 'form' is undefined
2018-09-28 11:03:33,485 INFO: Flaskblog startup [in C:\Users\Cleo\Documents\GitHub\FlaskBlog\app\__init__.py:49]
